Workbook

Sheet Dashboard
A2: ReefSafe decision dashboard
A3: Observed reef evidence + cautious next-observation screening | Malaysia, 2012–2025
A5: Selected island | B5: Labuan | E5: Change the yellow cell to inspect any monitored island
A7: Current LCC | D7: Observed change | G7: Predicted next change | J7: Priority
A8: =IFERROR(VLOOKUP($B$5,Priority_Data!$A$2:$M$41,4,FALSE),"") -> 24.23 | D8: =IFERROR(VLOOKUP($B$5,Priority_Data!$A$2:$M$41,5,FALSE),"") -> -7.345 | G8: =IFERROR(VLOOKUP($B$5,Priority_Data!$A$2:$M$41,7,FALSE),"") -> -14.417288 | J8: =IFERROR(VLOOKUP($B$5,Priority_Data!$A$2:$M$41,10,FALSE),"") -> High screening priority
A10: Uncertainty interval | B10: =IFERROR(TEXT(VLOOKUP($B$5,Priority_Data!$A$2:$M$41,8,FALSE),"0.0")&" to "&TEXT(VLOOKUP($B$5,Priority_Data!$A$2:$M$41,9,FALSE),"0.0")&" pp/yr","") -> -30.7 to -0.8 pp/yr | E10: Intervals are empirical screening bands, not causal or site-specific certainty.
A12: Observed evidence
A13: =IFERROR(VLOOKUP($B$5,Priority_Data!$A$2:$M$41,11,FALSE),"") -> NOAA thermal stress observed
A15: Recommended next step
A16: =IFERROR(VLOOKUP($B$5,Priority_Data!$A$2:$M$41,12,FALSE),"") -> Coordinate bleaching survey; do not attribute thermal loss to visitors
A37: Island | B37: State | C37: Current LCC | D37: Predicted change | E37: Evidence | H37: Model | I37: MAE | J37: RMSE | K37: R²
A38: =Priority_Data!A2 -> Labuan | B38: =Priority_Data!C2 -> W.P. Labuan | C38: =Priority_Data!D2 -> 24.23 | D38: =Priority_Data!G2 -> -14.417288 | E38: =Priority_Data!K2 -> NOAA thermal stress observed | H38: =Model_Check!A2 -> Baseline mean | I38: =Model_Check!B2 -> 5.991 | J38: =Model_Check!C2 -> 8.1 | K38: =Model_Check!D2 -> -0.019
A39: =Priority_Data!A3 -> Kapas | B39: =Priority_Data!C3 -> Terengganu | C39: =Priority_Data!D3 -> 52.63 | D39: =Priority_Data!G3 -> -5.7510548 | E39: =Priority_Data!K3 -> Modelled decline; no single dominant observed stressor | H39: =Model_Check!A3 -> Ridge regression | I39: =Model_Check!B3 -> 5.99 | J39: =Model_Check!C3 -> 7.939 | K39: =Model_Check!D3 -> 0.021
A40: =Priority_Data!A4 -> Seri Buat | B40: =Priority_Data!C4 -> Pahang | C40: =Priority_Data!D4 -> 54.22 | D40: =Priority_Data!G4 -> -5.1547029 | E40: =Priority_Data!K4 -> Anchor impact mentioned in Reef Check report | H40: =Model_Check!A4 -> Gradient boosting | I40: =Model_Check!B4 -> 5.862 | J40: =Model_Check!C4 -> 7.741 | K40: =Model_Check!D4 -> 0.069
A41: =Priority_Data!A5 -> Mertang | B41: =Priority_Data!C5 -> Johor | C41: =Priority_Data!D5 -> 58.33 | D41: =Priority_Data!G5 -> -5.0266139 | E41: =Priority_Data!K5 -> Anchor impact mentioned in Reef Check report | H41: =Model_Check!A5 -> Random forest | I41: =Model_Check!B5 -> 6.074 | J41: =Model_Check!C5 -> 8.016 | K41: =Model_Check!D5 -> 0.002
A42: =Priority_Data!A6 -> Mensirip | B42: =Priority_Data!C6 -> Johor | C42: =Priority_Data!D6 -> 54.17 | D42: =Priority_Data!G6 -> -4.8498589 | E42: =Priority_Data!K6 -> Waste or pollution indicator is elevated
A43: =Priority_Data!A7 -> Tenggol | B43: =Priority_Data!C7 -> Terengganu | C43: =Priority_Data!D7 -> 54.17 | D43: =Priority_Data!G7 -> -4.6395895 | E43: =Priority_Data!K7 -> Waste or pollution indicator is elevated | H43: Model check | I43: Gradient boosting MAE 5.86 pp/yr vs baseline 5.99 pp/yr (+2.1%). R² 0.069. NOAA heat is context only. Use the model to rank field checks, not as proof of tourism causality.
A44: =Priority_Data!A8 -> Tinggi | B44: =Priority_Data!C8 -> Johor | C44: =Priority_Data!D8 -> 52.5 | D44: =Priority_Data!G8 -> -4.6252273 | E44: =Priority_Data!K8 -> Anchor impact mentioned in Reef Check report
A45: =Priority_Data!A9 -> Lima | B45: =Priority_Data!C9 -> Johor | C45: =Priority_Data!D9 -> 51.88 | D45: =Priority_Data!G9 -> -4.3729979 | E45: =Priority_Data!K9 -> Anchor impact mentioned in Reef Check report
A46: =Priority_Data!A10 -> Sibu | B46: =Priority_Data!C10 -> Johor | C46: =Priority_Data!D10 -> 52.81 | D46: =Priority_Data!G10 -> -4.3361717 | E46: =Priority_Data!K10 -> Anchor impact mentioned in Reef Check report
A47: =Priority_Data!A11 -> Lankayan | B47: =Priority_Data!C11 -> Sabah | C47: =Priority_Data!D11 -> 51.04 | D47: =Priority_Data!G11 -> -4.0730636 | E47: =Priority_Data!K11 -> NOAA thermal stress observed

Sheet Priority_Data
A1: Island | B1: Rank | C1: State | D1: Current LCC (%) | E1: Observed change (pp/yr) | F1: Max DHW (context only) | G1: Predicted next change (pp/yr) | H1: Lower | I1: Upper | J1: Priority tier | K1: Evidence | L1: Recommended next step | M1: Source confidence
A2: Labuan | B2: 1 | C2: W.P. Labuan | D2: 24.23 | E2: -7.345 | F2: 4.04 | G2: -14.417288 | H2: -30.671674 | I2: -0.75527129 | J2: High screening priority | K2: NOAA thermal stress observed | L2: Coordinate bleaching survey; do not attribute thermal loss to visitors | M2: PDF geometry only - not cross-checked
A3: Kapas | B3: 2 | C3: Terengganu | D3: 52.63 | E3: 5.11 | F3: 2.05 | G3: -5.7510548 | H3: -22.00544 | I3: 7.9109621 | J3: High screening priority | K3: Modelled decline; no single dominant observed stressor | L3: Prioritise field validation before imposing restrictions | M3: mixed - markdown primary, PDF filled gaps
A4: Seri Buat | B4: 3 | C4: Pahang | D4: 54.22 | E4: -7.84 | F4: 2.05 | G4: -5.1547029 | H4: -21.409088 | I4: 8.5073141 | J4: High screening priority | K4: Anchor impact mentioned in Reef Check report | L4: Inspect mooring availability and anchoring controls | M4: mixed - markdown primary, PDF filled gaps
A5: Mertang | B5: 4 | C5: Johor | D5: 58.33 | E5: -11.25 | F5: 1.88 | G5: -5.0266139 | H5: -21.280999 | I5: 8.6354031 | J5: High screening priority | K5: Anchor impact mentioned in Reef Check report | L5: Inspect mooring availability and anchoring controls | M5: mixed - markdown primary, PDF filled gaps
A6: Mensirip | B6: 5 | C6: Johor | D6: 54.17 | E6: -4.66 | F6: 1.88 | G6: -4.8498589 | H6: -21.104244 | I6: 8.812158 | J6: High screening priority | K6: Waste or pollution indicator is elevated | L6: Inspect waste and wastewater controls | M6: mixed - markdown primary, PDF filled gaps
A7: Tenggol | B7: 6 | C7: Terengganu | D7: 54.17 | E7: -2.91 | F7: 2.05 | G7: -4.6395895 | H7: -20.893975 | I7: 9.0224275 | J7: High screening priority | K7: Waste or pollution indicator is elevated | L7: Inspect waste and wastewater controls | M7: mixed - markdown primary, PDF filled gaps
A8: Tinggi | B8: 7 | C8: Johor | D8: 52.5 | E8: -4.22 | F8: 1.88 | G8: -4.6252273 | H8: -20.879613 | I8: 9.0367897 | J8: High screening priority | K8: Anchor impact mentioned in Reef Check report | L8: Inspect mooring availability and anchoring controls | M8: mixed - markdown primary, PDF filled gaps
A9: Lima | B9: 8 | C9: Johor | D9: 51.88 | E9: -10.4 | F9: 1.88 | G9: -4.3729979 | H9: -20.627383 | I9: 9.2890191 | J9: High screening priority | K9: Anchor impact mentioned in Reef Check report | L9: Inspect mooring availability and anchoring controls | M9: mixed - markdown primary, PDF filled gaps
A10: Sibu | B10: 9 | C10: Johor | D10: 52.81 | E10: 2.08 | F10: 1.88 | G10: -4.3361717 | H10: -20.590557 | I10: 9.3258453 | J10: High screening priority | K10: Anchor impact mentioned in Reef Check report | L10: Inspect mooring availability and anchoring controls | M10: mixed - markdown primary, PDF filled gaps
A11: Lankayan | B11: 10 | C11: Sabah | D11: 51.04 | E11: 1.51 | F11: 4.04 | G11: -4.0730636 | H11: -20.327449 | I11: 9.5889534 | J11: High screening priority | K11: NOAA thermal stress observed | L11: Coordinate bleaching survey; do not attribute thermal loss to visitors | M11: mixed - markdown primary, PDF filled gaps
A12: Sipadan | B12: 11 | C12: Sabah | D12: 55.21 | E12: -8.08 | F12: 4.04 | G12: -4.0610458 | H12: -20.315431 | I12: 9.6009712 | J12: Monitor | K12: NOAA thermal stress observed | L12: Coordinate bleaching survey; do not attribute thermal loss to visitors | M12: mixed - markdown primary, PDF filled gaps
A13: Tun Sakaran Marine Park | B13: 12 | C13: Sabah | D13: 51.77 | E13: -4.01 | F13: 4.04 | G13: -3.9730663 | H13: -20.227452 | I13: 9.6889507 | J13: Monitor | K13: NOAA thermal stress observed | L13: Coordinate bleaching survey; do not attribute thermal loss to visitors | M13: mixed - markdown primary, PDF filled gaps
... A41: Malacca | B41: 40 | C41: Malacca | D41: 32.12 | E41: -1.04 | F41: 2.05 | G41: 3.4835404 | H41: -12.770845 | I41: 17.145557 | J41: Monitor | K41: Anchor impact mentioned in Reef Check report | L41: Inspect mooring availability and anchoring controls | M41: PDF geometry only - not cross-checked

Sheet History_Data
A1: Island | B1: State | C1: Survey year | D1: Live coral cover (%) | E1: Observed change (pp/yr) | F1: Max DHW (context only) | G1: Source confidence
A2: Tioman | B2: Pahang | C2: 2012 | D2: 55.81 | F2: 0.15 | G2: PDF geometry only - not cross-checked
A3: Kapas | B3: Terengganu | C3: 2012 | D3: 58.43 | F3: 0.33 | G3: PDF geometry only - not cross-checked
A4: Babi Tengah | B4: Johor | C4: 2013 | D4: 63.7 | F4: 1.32 | G4: PDF geometry only - not cross-checked
A5: Pemanggil | B5: Johor | C5: 2013 | D5: 48.78 | F5: 1.32 | G5: mixed - markdown primary, PDF filled gaps
A6: Sibu & Tinggi | B6: Johor | C6: 2013 | D6: 55.84 | F6: 1.32 | G6: mixed - markdown primary, PDF filled gaps
A7: Tioman | B7: Pahang | C7: 2013 | D7: 55.81 | E7: 0 | F7: 1.32 | G7: markdown only
A8: Sembilan | B8: Perak | C8: 2013 | D8: 44.61 | F8: 2.69 | G8: mixed - markdown primary, PDF filled gaps
A9: Kota Belud | B9: Sabah | C9: 2013 | D9: 17.41 | F9: 1.88 | G9: mixed - markdown primary, PDF filled gaps
A10: Labuan | B10: W.P. Labuan | C10: 2013 | D10: 56.23 | F10: 1.88 | G10: mixed - markdown primary, PDF filled gaps
A11: Lahad Datu | B11: Sabah | C11: 2013 | D11: 40.87 | F11: 1.88 | G11: mixed - markdown primary, PDF filled gaps
A12: Lankayan | B12: Sabah | C12: 2013 | D12: 54.04 | F12: 1.88 | G12: mixed - markdown primary, PDF filled gaps
A13: Mantanani | B13: Sabah | C13: 2013 | D13: 40.63 | F13: 1.88 | G13: verified - markdown corrected an error in the PDF pass
A14: Mataking | B14: Sabah | C14: 2013 | D14: 36.29 | F14: 1.88 | G14: mixed - markdown primary, PDF filled gaps
A15: Semporna | B15: Sabah | C15: 2013 | D15: 25.98 | F15: 1.88 | G15: mixed - markdown primary, PDF filled gaps
A16: Tun Sakaran Marine Park | B16: Sabah | C16: 2013 | D16: 43.2 | F16: 1.88 | G16: mixed - markdown primary, PDF filled gaps
A17: Tunku Abdul Rahman Park | B17: Sabah | C17: 2013 | D17: 40 | F17: 1.88 | G17: mixed - markdown primary, PDF filled gaps
A18: Kuching | B18: Sarawak | C18: 2013 | D18: 75.7 | F18: 1.85 | G18: mixed - markdown primary, PDF filled gaps
A19: Miri | B19: Sarawak | C19: 2013 | D19: 53.1 | F19: 1.85 | G19: mixed - markdown primary, PDF filled gaps
A20: Bidong & Yu | B20: Terengganu | C20: 2013 | D20: 54.53 | F20: 2.73 | G20: mixed - markdown primary, PDF filled gaps
A21: Kapas | B21: Terengganu | C21: 2013 | D21: 58.43 | E21: 0 | F21: 2.73 | G21: markdown only
A22: Perhentian | B22: Terengganu | C22: 2013 | D22: 56.63 | F22: 2.73 | G22: PDF geometry only - not cross-checked
A23: Redang | B23: Terengganu | C23: 2013 | D23: 54.83 | F23: 2.73 | G23: mixed - markdown primary, PDF filled gaps
A24: Tenggol | B24: Terengganu | C24: 2013 | D24: 56.2 | F24: 2.73 | G24: mixed - markdown primary, PDF filled gaps
A25: Pemanggil | B25: Johor | C25: 2014 | D25: 54.07 | E25: 5.29 | F25: 1.47 | G25: mixed - markdown primary, PDF filled gaps
A26: Sibu | B26: Johor | C26: 2014 | D26: 46.66 | F26: 1.47 | G26: mixed - markdown primary, PDF filled gaps
A27: Tinggi | B27: Johor | C27: 2014 | D27: 61.88 | F27: 1.47 | G27: mixed - markdown primary, PDF filled gaps
A28: Tioman | B28: Pahang | C28: 2014 | D28: 60.4 | E28: 4.59 | F28: 1.47 | G28: mixed - markdown primary, PDF filled gaps
A29: Pangkor Laut | B29: Perak | C29: 2014 | D29: 55.63 | F29: 1.2 | G29: mixed - markdown primary, PDF filled gaps
A30: Sembilan | B30: Perak | C30: 2014 | D30: 33.91 | E30: -10.7 | F30: 1.2 | G30: mixed - markdown primary, PDF filled gaps
A31: Lahad Datu | B31: Sabah | C31: 2014 | D31: 41.58 | E31: 0.71 | F31: 5.17 | G31: mixed - markdown primary, PDF filled gaps
A32: Lankayan | B32: Sabah | C32: 2014 | D32: 46.29 | E32: -7.75 | F32: 5.17 | G32: mixed - markdown primary, PDF filled gaps
A33: Mantanani | B33: Sabah | C33: 2014 | D33: 43.3 | E33: 2.67 | F33: 5.17 | G33: markdown only
A34: Mataking & Pom Pom | B34: Sabah | C34: 2014 | D34: 27.04 | F34: 5.17 | G34: mixed - markdown primary, PDF filled gaps
A35: Semporna | B35: Sabah | C35: 2014 | D35: 39.94 | E35: 13.96 | F35: 5.17 | G35: mixed - markdown primary, PDF filled gaps
A36: Sipadan | B36: Sabah | C36: 2014 | D36: 60.4 | F36: 5.17 | G36: mixed - markdown primary, PDF filled gaps
A37: Tun Sakaran Marine Park | B37: Sabah | C37: 2014 | D37: 50.4 | E37: 7.2 | F37: 5.17 | G37: mixed - markdown primary, PDF filled gaps
A38: Tunku Abdul Rahman Park | B38: Sabah | C38: 2014 | D38: 38.46 | E38: -1.54 | F38: 5.17 | G38: mixed - markdown primary, PDF filled gaps
A39: Usukan Cove | B39: Sabah | C39: 2014 | D39: 38.44 | F39: 5.17 | G39: mixed - markdown primary, PDF filled gaps
A40: Kuching | B40: Sarawak | C40: 2014 | D40: 55 | E40: -20.7 | F40: 1.24 | G40: mixed - markdown primary, PDF filled gaps
...

Sheet Model_Check
A1: Model | B1: MAE (pp/yr) | C1: RMSE (pp/yr) | D1: R² | F1: Check | G1: Value
A2: Baseline mean | B2: 5.991 | C2: 8.1 | D2: -0.019 | F2: Evaluation design | G2: Expanding-window evaluation on the five latest target years
A3: Ridge regression | B3: 5.99 | C3: 7.939 | D3: 0.021 | F3: Forward evaluation rows | G3: 183
A4: Gradient boosting | B4: 5.862 | C4: 7.741 | D4: 0.069 | F4: Best-model MAE improvement | G4: 0.021488199
A5: Random forest | B5: 6.074 | C5: 8.016 | D5: 0.002 | F5: Decision status | G5: Screening only. NOAA heat is context, not a production-model feature.
F7: Survey year | G7: National mean LCC (%)
F8: 2012 | G8: 57.12
F9: 2013 | G9: 49.181429
F10: 2014 | G10: 49.192273
F11: 2015 | G11: 47.31
F12: 2016 | G12: 44.462963
F13: 2017 | G13: 43.265517
F14: 2018 | G14: 41.34
F15: 2019 | G15: 42.153333
F16: 2020 | G16: 41.3584
F17: 2021 | G17: 43.638571
F18: 2022 | G18: 47.55814
F19: 2023 | G19: 46.798864
... F21: 2025 | G21: 39.8185
